
# Created by Ruins mod version 17.1 Ingame Parser
# authoring Player: Griefed

weight=1
embed_into_distance=1
unacceptable_target_blocks=flowing_water,water,flowing_lava,lava,Natura:Cloud,red_mushroom_block,brown_mushroom_block,planks,cobblestone,end_stone,obsidian,purpur_block,iron_bars,purpur_slab,purpur_pillar,netherrack,soul_sand,quartz_ore
dimensions=7,12,7
allowable_overhang=0
max_leveling=1
leveling_buffer=0
preserve_water=0
preserve_lava=0
preserve_plants=0
preventRotation=1

rule1=0,100,minecraft:stonebrick-0
rule2=0,100,minecraft:stonebrick-1
rule3=0,100,minecraft:stonebrick-2
rule4=0,100,minecraft:stonebrick-3
rule5=0,100,minecraft:stone_brick_stairs-1
rule6=0,100,sgcraft:stargatering-0
rule7=0,100,sgcraft:stargatering-1
rule8=0,100,sgcraft:stargatebase-0
rule9=0,100,sgcraft:stargatecontroller-0

layer
1,3,2,3,2,3,1
1,1,1,1,1,1,2
3,1,1,1,1,1,3
3,1,1,1,1,1,1
2,1,1,1,1,1,3
3,1,1,1,1,1,1
3,3,2,2,3,3,1
3,3,3,3,3,3,2
2,2,3,1,2,3,2
2,3,3,1,2,3,1
3,3,1,1,3,3,3
3,1,2,2,1,3,1
endlayer

layer
4,1,3,3,2,1,4
2,0,0,0,0,0,3
1,0,0,0,0,0,3
3,0,0,0,0,0,2
3,1,1,1,1,1,2
4,5,5,5,5,5,4
3,0,0,0,0,0,1
0,0,0,0,0,0,0
0,0,0,9,0,0,0
0,0,0,0,0,0,0
0,0,0,0,0,0,0
4,0,0,0,0,0,4
endlayer

layer
4,1,1,1,1,1,4
2,7,6,8,6,7,3
3,1,1,1,1,1,3
2,3,2,3,3,3,3
2,5,5,5,5,5,3
4,0,0,0,0,0,4
5,0,0,0,0,0,5
0,0,0,0,0,0,0
0,0,0,0,0,0,0
0,0,0,0,0,0,0
0,0,0,0,0,0,0
4,0,0,0,0,0,4
endlayer

layer
4,0,0,0,0,0,4
0,6,0,0,0,6,0
0,0,0,0,0,0,0
0,0,0,0,0,0,0
0,0,0,0,0,0,0
4,0,0,0,0,0,4
0,0,0,0,0,0,0
0,0,0,0,0,0,0
0,0,0,0,0,0,0
0,0,0,0,0,0,0
0,0,0,0,0,0,0
0,0,0,0,0,0,0
endlayer

layer
4,0,0,0,0,0,4
0,7,0,0,0,7,0
0,0,0,0,0,0,0
0,0,0,0,0,0,0
0,0,0,0,0,0,0
4,0,0,0,0,0,4
0,0,0,0,0,0,0
0,0,0,0,0,0,0
0,0,0,0,0,0,0
0,0,0,0,0,0,0
0,0,0,0,0,0,0
0,0,0,0,0,0,0
endlayer

layer
4,0,0,0,0,0,4
0,6,0,0,0,6,0
0,0,0,0,0,0,0
0,0,0,0,0,0,0
0,0,0,0,0,0,0
4,0,0,0,0,0,4
0,0,0,0,0,0,0
0,0,0,0,0,0,0
0,0,0,0,0,0,0
0,0,0,0,0,0,0
0,0,0,0,0,0,0
0,0,0,0,0,0,0
endlayer

layer
4,0,0,0,0,0,4
0,7,6,7,6,7,0
0,0,0,0,0,0,0
0,0,0,0,0,0,0
0,0,0,0,0,0,0
0,0,0,0,0,0,0
0,0,0,0,0,0,0
0,0,0,0,0,0,0
0,0,0,0,0,0,0
0,0,0,0,0,0,0
0,0,0,0,0,0,0
0,0,0,0,0,0,0
endlayer